<?xml version="1.0" ?>
<!-- =================================================================================== -->
<!-- |    This document was autogenerated by xacro from quadrotor.urdf.xacro           | -->
<!-- |    EDITING THIS FILE BY HAND IS NOT RECOMMENDED                                 | -->
<!-- =================================================================================== -->
<robot name="quadrotor_full" xmlns:xacro="http://wiki.ros.org/xacro">
  <!-- Included URDF Files -->
  <!-- Bais link of quadrotor-->
  <link name="base_Link">
    <inertial>
      <origin rpy="1.5708 0 1.5708" xyz="0 0 -0.052"/>
      <mass value="0.7"/>
      <inertia ixx="0.0027947" ixy="0" ixz="0" iyy="0.00278554" iyz="0" izz="0.004656638"/>
    </inertial>
    <visual>
      <origin rpy="1.5708 0 1.5708" xyz="0 0 -0.052"/>
      <geometry>
        <mesh filename="package://quad_description/meshes/quadrotor/base_Link.dae"/>
      </geometry>
    </visual>
    <collision>
      <origin rpy="0 0 0" xyz="0 0 0"/>
      <geometry>
        <mesh filename="package://quad_description/meshes/quadrotor/base_Link.STL"/>
      </geometry>
    </collision>
  </link>
  <!-- Front Right Prop -->
  <link name="FR_Link">
    <inertial>
      <origin rpy="1.5708 0 -0.523599" xyz="-0.003 0 0"/>
      <mass value="0.007"/>
      <inertia ixx="0.00002353" ixy="0" ixz="0" iyy="0.00002353" iyz="0" izz="0.00004706"/>
    </inertial>
    <visual>
      <origin rpy="1.57 0 -0.523599" xyz="-0.003 0 0"/>
      <geometry>
        <mesh filename="package://quad_description/meshes/quadrotor/FR_Link.dae"/>
      </geometry>
    </visual>
    <collision>
      <origin rpy="0 0 0" xyz="0 0 0"/>
      <geometry>
        <mesh filename="package://quad_description/meshes/quadrotor/FR_Link.STL"/>
      </geometry>
    </collision>
  </link>
  <!-- Front Right Joint -->
  <joint name="FR_Joint" type="continuous">
    <origin rpy="0 0 0" xyz="0.0714 -0.1153345227 0.026"/>
    <parent link="base_Link"/>
    <child link="FR_Link"/>
    <axis xyz="0 0 1"/>
  </joint>
  <!-- Back Left Prop -->
  <link name="BL_Link">
    <inertial>
      <origin rpy="1.5708 0 1.0472" xyz="-0.001 -0.003 0"/>
      <mass value="0.007"/>
      <inertia ixx="0.00002353" ixy="0" ixz="0" iyy="0.00002353" iyz="0" izz="0.00004706"/>
    </inertial>
    <visual>
      <origin rpy="1.5708 0 1.0472" xyz="-0.001 -0.003 0"/>
      <geometry>
        <mesh filename="package://quad_description/meshes/quadrotor/BL_Link.dae"/>
      </geometry>
    </visual>
    <collision>
      <origin rpy="0 -1.5708 0" xyz="0 0.003 0"/>
      <geometry>
        <mesh filename="package://quad_description/meshes/quadrotor/BL_Link.STL"/>
      </geometry>
    </collision>
  </link>
  <!-- Back Left Joint -->
  <joint name="BL_Joint" type="continuous">
    <origin rpy="0 0 0" xyz="-0.07161128 0.1148345227 0.026"/>
    <parent link="base_Link"/>
    <child link="BL_Link"/>
    <axis xyz="0 0 1"/>
  </joint>
  <!-- Back Right Prop -->
  <link name="BR_Link">
    <inertial>
      <origin rpy="1.5708 0 1.0472" xyz="-0.002 -0.003 0"/>
      <mass value="0.007"/>
      <inertia ixx="0.00002353" ixy="0" ixz="0" iyy="0.00002353" iyz="0" izz="0.00004706"/>
    </inertial>
    <visual>
      <origin rpy="1.5708 0 1.0472" xyz="-0.002 -0.003 0"/>
      <geometry>
        <mesh filename="package://quad_description/meshes/quadrotor/BR_Link.dae"/>
      </geometry>
    </visual>
    <collision>
      <origin rpy="0 0 0" xyz="0 0 0"/>
      <geometry>
        <mesh filename="package://quad_description/meshes/quadrotor/BR_Link.STL"/>
      </geometry>
    </collision>
  </link>
  <!-- Back Right Joint -->
  <joint name="BR_Joint" type="continuous">
    <origin rpy="0 0 0" xyz="-0.0716112686755679 -0.115430836109892 0.026"/>
    <parent link="base_Link"/>
    <child link="BR_Link"/>
    <axis xyz="0 0 1"/>
  </joint>
  <!-- Front Left Prop -->
  <link name="FL_Link">
    <inertial>
      <origin rpy="1.5708 0 0" xyz="-0.002 -0.001 0"/>
      <mass value="0.007"/>
      <inertia ixx="0.00002353" ixy="0" ixz="0" iyy="0.00002353" iyz="0" izz="0.00004706"/>
    </inertial>
    <visual>
      <origin rpy="1.5708 0 0" xyz="-0.002 -0.001 0"/>
      <geometry>
        <mesh filename="package://quad_description/meshes/quadrotor/FL_Link.dae"/>
      </geometry>
    </visual>
    <collision>
      <origin rpy="1.5708 0 0" xyz="-0.002 -0.001 0"/>
      <geometry>
        <mesh filename="package://quad_description/meshes/quadrotor/FL_Link.STL"/>
      </geometry>
    </collision>
  </link>
  <!-- Front Left Prop -->
  <joint name="FL_Joint" type="continuous">
    <origin rpy="0 0 0" xyz="0.0712 0.114834 0.026"/>
    <parent link="base_Link"/>
    <child link="FL_Link"/>
    <axis xyz="0 0 1"/>
  </joint>
  <!-- IMU, Baro, Magnetic, GPS, Groundtruth sensors -->
  <gazebo>
    <plugin filename="libhector_gazebo_ros_imu.so" name="quadrotor_imu_sim">
      <alwaysOn>true</alwaysOn>
      <updateRate>100.0</updateRate>
      <bodyName>base_Link</bodyName>
      <frameId>quadrotor_base_Link</frameId>
      <topicName>/quadrotor_1/imu</topicName>
      <xyzOffset>0 0 0</xyzOffset>
      <rpyOffset>0 0 0</rpyOffset>
      <gaussianNoise>0</gaussianNoise>
      <!-- deprecated -->
      <accelDrift>0.5 0.5 0.5</accelDrift>
      <accelGaussianNoise>0.35 0.35 0.3</accelGaussianNoise>
      <rateDrift>0.0 0.0 0.0</rateDrift>
      <rateGaussianNoise>0.00 0.00 0.00</rateGaussianNoise>
      <headingDrift>0.0</headingDrift>
      <headingGaussianNoise>0.00</headingGaussianNoise>
    </plugin>
    <plugin filename="libhector_gazebo_ros_baro.so" name="quadrotor_baro_sim">
      <alwaysOn>true</alwaysOn>
      <updateRate>10.0</updateRate>
      <bodyName>base_Link</bodyName>
      <topicName>/quadrotor_1/pressure_height</topicName>
      <altimeterTopicName>altimeter</altimeterTopicName>
      <offset>0</offset>
      <drift>0.1</drift>
      <gaussianNoise>0.5</gaussianNoise>
    </plugin>
    <plugin filename="libhector_gazebo_ros_magnetic.so" name="quadrotor_magnetic_sim">
      <alwaysOn>true</alwaysOn>
      <updateRate>10.0</updateRate>
      <bodyName>base_Link</bodyName>
      <topicName>/quadrotor_1/magnetic</topicName>
      <offset>0 0 0</offset>
      <drift>0.0 0.0 0.0</drift>
      <gaussianNoise>1.3e-2 1.3e-2 1.3e-2</gaussianNoise>
    </plugin>
    <plugin filename="libhector_gazebo_ros_gps.so" name="quadrotor_gps_sim">
      <alwaysOn>true</alwaysOn>
      <updateRate>4.0</updateRate>
      <bodyName>base_Link</bodyName>
      <topicName>/quadrotor_1/fix</topicName>
      <velocityTopicName>/quadrotor_1/fix_velocity</velocityTopicName>
      <drift>5.0 5.0 5.0</drift>
      <gaussianNoise>0.1 0.1 0.1</gaussianNoise>
      <velocityDrift>0 0 0</velocityDrift>
      <velocityGaussianNoise>0.1 0.1 0.1</velocityGaussianNoise>
    </plugin>
    <plugin filename="libgazebo_ros_p3d.so" name="quadrotor_groundtruth_sim">
      <alwaysOn>true</alwaysOn>
      <updateRate>100.0</updateRate>
      <bodyName>base_Link</bodyName>
      <topicName>/quadrotor_1/ground_truth/state</topicName>
      <gaussianNoise>0.0</gaussianNoise>
      <frameName>map</frameName>
    </plugin>
  </gazebo>
  <!-- 4D velocity control -->
  <!-- Quadrotor Simple Controller Plugin -->
  <gazebo>
    <plugin filename="/home/aminys/quad_ws/src/quad_control/plugins/build/libQuadrotor_Plugin.so" name="quadrotor_plugin_force_torque"/>
  </gazebo>
  <joint name="sonar_joint" type="fixed">
    <origin rpy="0 1.57079632679 0" xyz="-0.045 0.0 -0.052"/>
    <parent link="base_Link"/>
    <child link="sonar_link"/>
  </joint>
  <link name="sonar_link">
    <inertial>
      <mass value="0.001"/>
      <origin rpy="0 0 0" xyz="0 0 0"/>
      <inertia ixx="0.000000017" ixy="0" ixz="0" iyy="0.000000017" iyz="0" izz="0.000000017"/>
    </inertial>
    <visual>
      <origin rpy="0 0 0" xyz="0 0 0"/>
      <geometry>
        <!--<box size="0.01 0.01 0.01" /> -->
        <mesh filename="package://quad_description/meshes/sonar_sensor/max_sonar_ez4.dae"/>
      </geometry>
    </visual>
    <collision>
      <origin rpy="0 0 0" xyz="0 0 0"/>
      <geometry>
        <box size="0.01 0.01 0.01"/>
      </geometry>
    </collision>
  </link>
  <gazebo reference="sonar_link">
    <sensor name="sonar" type="ray">
      <update_rate>10</update_rate>
      <ray>
        <range>
          <min>0.01</min>
          <max>3.0</max>
          <resolution>0.01</resolution>
        </range>
        <scan>
          <horizontal>
            <samples>3</samples>
            <min_angle>-0.349065850399</min_angle>
            <max_angle>0.349065850399</max_angle>
          </horizontal>
          <vertical>
            <samples>3</samples>
            <min_angle>-0.349065850399</min_angle>
            <max_angle>0.349065850399</max_angle>
          </vertical>
        </scan>
      </ray>
      <plugin filename="libhector_gazebo_ros_sonar.so" name="gazebo_ros_sonar_controller">
        <gaussianNoise>0.000</gaussianNoise>
        <topicName>/quadrotor_1/sonar_height</topicName>
        <frameId>sonar_link</frameId>
      </plugin>
    </sensor>
  </gazebo>
  <!-- Hokuyo UTM-30LX mounted upside down below the quadrotor body -->
  <!--
    <xacro:include filename="$(find quad_description)/urdf/sensors/hokuyo_utm30lx.urdf.xacro" />
    <xacro:hokuyo_utm30lx name="laser0" robot_name="${robot_name}" parent="base_Link" ros_topic="scan" update_rate="40" ray_count="1081" min_angle="135" max_angle="-135">
      <origin xyz="0.0 0.0 0.08" rpy="${M_PI} 0 0"/>
    </xacro:hokuyo_utm30lx>
-->
  <!-- Forward facing camera -->
  <!--
    <xacro:include filename="$(find quad_description)/urdf/sensors/generic_camera.urdf.xacro" />
    <xacro:generic_camera name="front" robot_name="${robot_name}" parent="base_link" update_rate="60" res_x="640" res_y="360" image_format="R8G8B8" hfov="${81*M_PI/180}">
      <origin xyz="0.21 0.0 0.01" rpy="0 0 0"/>
    </xacro:generic_camera>
-->
  <joint name="bottom_joint" type="fixed">
    <origin rpy="0 1.57079632679 0" xyz="0.0 0.0 -0.057"/>
    <parent link="base_Link"/>
    <child link="bottom_link"/>
  </joint>
  <link name="bottom_link">
    <inertial>
      <mass value="0.001"/>
      <origin rpy="0 0 0" xyz="0 0 0"/>
      <inertia ixx="0.0001" ixy="0" ixz="0" iyy="0.0001" iyz="0" izz="0.0001"/>
    </inertial>
    <visual>
      <origin rpy="0 0 0" xyz="0 0 0"/>
      <geometry>
        <box size="0.01 0.01 0.01"/>
      </geometry>
      <material name="Blue">
        <color rgba="0.0 0.0 0.8 1"/>
      </material>
    </visual>
    <collision>
      <origin rpy="0 0 0" xyz="0 0 0"/>
      <geometry>
        <box size="0.01 0.01 0.01"/>
      </geometry>
    </collision>
  </link>
  <joint name="bottom_optical_joint" type="fixed">
    <origin rpy="-1.57079632679 0.0 -1.57079632679" xyz="0 0 0"/>
    <parent link="bottom_link"/>
    <child link="ardrone_base_bottomcam"/>
  </joint>
  <link name="ardrone_base_bottomcam">
    <inertial>
      <mass value="0.01"/>
      <origin xyz="0 0 0"/>
      <inertia ixx="0.001" ixy="0.0" ixz="0.0" iyy="0.001" iyz="0.0" izz="0.001"/>
    </inertial>
    <visual>
      <origin rpy="0 0 0" xyz="0 0 0"/>
      <geometry>
        <box size="0.001 0.001 0.001"/>
      </geometry>
    </visual>
    <collision>
      <origin rpy="0 0 0" xyz="0 0 0"/>
      <geometry>
        <box size="0.001 0.001 0.001"/>
      </geometry>
    </collision>
  </link>
  <gazebo reference="bottom_link">
    <sensor name="bottom_camera_sensor" type="camera">
      <update_rate>25</update_rate>
      <camera name="head">
        <horizontal_fov>1.41371669412</horizontal_fov>
        <image>
          <width>320</width>
          <height>240</height>
          <format>R8G8B8</format>
        </image>
        <clip>
          0.01
	      
          <near>0.01</near>
          <far>100</far>
        </clip>
      </camera>
      <plugin filename="libgazebo_ros_camera.so" name="bottom_camera_controller">
        <robotNamespace>quadrotor_1</robotNamespace>
        <cameraName>bottom</cameraName>
        <alwaysOn>true</alwaysOn>
        <updateRate>25</updateRate>
        <imageTopicName>image_raw</imageTopicName>
        <cameraInfoTopicName>camera_info</cameraInfoTopicName>
        <frameName>ardrone_base_bottomcam</frameName>
      </plugin>
    </sensor>
    <!--<turnGravityOff>true</turnGravityOff>-->
    <material>PR2/Blue</material>
  </gazebo>
</robot>

